Workbook

Sheet 2009_Winner_Expenses
A1: Sno | B1: Candidate | C1: Constituency | D1: Party | E1: Total Expenses in election | F1: State | G1: Constituency No.
A2: 1 | B2: A.T. NANA PATIL | C2: Jalgaon | D2: BJP | E2: Rs 14,74,623 | F2: =_xlfn.XLOOKUP(C2,'State-wise constituency (2009)'!$C:$C,'State-wise constituency (2009)'!$A:$A,"Not Found") -> Maharashtra | G2: =_xlfn.XLOOKUP(C2,'State-wise constituency (2009)'!$C:$C,'State-wise constituency (2009)'!$B:$B,"Not Found") -> 3
A3: 2 | B3: AARON RASHID.J.M | C3: Theni | D3: INC | E3: Rs 4,61,540 | F3: =_xlfn.XLOOKUP(C3,'State-wise constituency (2009)'!$C:$C,'State-wise constituency (2009)'!$A:$A,"Not Found") -> Tamil Nadu | G3: =_xlfn.XLOOKUP(C3,'State-wise constituency (2009)'!$C:$C,'State-wise constituency (2009)'!$B:$B,"Not Found") -> 33
A4: 3 | B4: AAWALE JAYWANT GANGARAM | C4: Latur | D4: INC | E4: Rs 23,16,213 | F4: =_xlfn.XLOOKUP(C4,'State-wise constituency (2009)'!$C:$C,'State-wise constituency (2009)'!$A:$A,"Not Found") -> Maharashtra | G4: =_xlfn.XLOOKUP(C4,'State-wise constituency (2009)'!$C:$C,'State-wise constituency (2009)'!$B:$B,"Not Found") -> 41
A5: 4 | B5: ABDUL MANNAN HOSSAIN | C5: Murshidabad | D5: INC | E5: Rs 12,85,460 | F5: =_xlfn.XLOOKUP(C5,'State-wise constituency (2009)'!$C:$C,'State-wise constituency (2009)'!$A:$A,"Not Found") -> West Bengal | G5: =_xlfn.XLOOKUP(C5,'State-wise constituency (2009)'!$C:$C,'State-wise constituency (2009)'!$B:$B,"Not Found") -> 11
A6: 5 | B6: ABDULRAHMAN | C6: Vellore | D6: DMK | E6: Rs 14,80,724 | F6: =_xlfn.XLOOKUP(C6,'State-wise constituency (2009)'!$C:$C,'State-wise constituency (2009)'!$A:$A,"Not Found") -> Tamil Nadu | G6: =_xlfn.XLOOKUP(C6,'State-wise constituency (2009)'!$C:$C,'State-wise constituency (2009)'!$B:$B,"Not Found") -> 8
A7: 6 | B7: Abu Hasem Khan Choudhury | C7: Maldaha Dakshin | D7: INC | E7: Rs 15,97,521 | F7: =_xlfn.XLOOKUP(C7,'State-wise constituency (2009)'!$C:$C,'State-wise constituency (2009)'!$A:$A,"Not Found") -> West Bengal | G7: =_xlfn.XLOOKUP(C7,'State-wise constituency (2009)'!$C:$C,'State-wise constituency (2009)'!$B:$B,"Not Found") -> 8
A8: 7 | B8: Acharia Basudeb | C8: Bankura | D8: CPM | E8: Rs 13,20,108 | F8: =_xlfn.XLOOKUP(C8,'State-wise constituency (2009)'!$C:$C,'State-wise constituency (2009)'!$A:$A,"Not Found") -> West Bengal | G8: =_xlfn.XLOOKUP(C8,'State-wise constituency (2009)'!$C:$C,'State-wise constituency (2009)'!$B:$B,"Not Found") -> 36
A9: 8 | B9: AD.KAMAT GURUDAS VASANT | C9: Mumbai North West | D9: INC | E9: Rs 11,51,222 | F9: =_xlfn.XLOOKUP(C9,'State-wise constituency (2009)'!$C:$C,'State-wise constituency (2009)'!$A:$A,"Not Found") -> Not Found | G9: =_xlfn.XLOOKUP(C9,'State-wise constituency (2009)'!$C:$C,'State-wise constituency (2009)'!$B:$B,"Not Found") -> Not Found
A10: 9 | B10: ADAGUR H. VISWANATH | C10: Mysore | D10: INC | E10: Rs 15,87,295 | F10: =_xlfn.XLOOKUP(C10,'State-wise constituency (2009)'!$C:$C,'State-wise constituency (2009)'!$A:$A,"Not Found") -> Karnataka | G10: =_xlfn.XLOOKUP(C10,'State-wise constituency (2009)'!$C:$C,'State-wise constituency (2009)'!$B:$B,"Not Found") -> 21
A11: 10 | B11: ADHALRAO SHIVAJI DATTATRAY | C11: Shirur | D11: SHS | E11: Rs 19,11,500 | F11: =_xlfn.XLOOKUP(C11,'State-wise constituency (2009)'!$C:$C,'State-wise constituency (2009)'!$A:$A,"Not Found") -> Maharashtra | G11: =_xlfn.XLOOKUP(C11,'State-wise constituency (2009)'!$C:$C,'State-wise constituency (2009)'!$B:$B,"Not Found") -> 36
A12: 11 | B12: ADHIKARI SISIR KUMAR | C12: Kanthi | D12: AITC | E12: Rs 9,80,791 | F12: =_xlfn.XLOOKUP(C12,'State-wise constituency (2009)'!$C:$C,'State-wise constituency (2009)'!$A:$A,"Not Found") -> West Bengal | G12: =_xlfn.XLOOKUP(C12,'State-wise constituency (2009)'!$C:$C,'State-wise constituency (2009)'!$B:$B,"Not Found") -> 31
A13: 12 | B13: ADHIKARI SUVENDU | C13: Tamluk | D13: AITC | E13: Rs 12,74,375 | F13: =_xlfn.XLOOKUP(C13,'State-wise constituency (2009)'!$C:$C,'State-wise constituency (2009)'!$A:$A,"Not Found") -> West Bengal | G13: =_xlfn.XLOOKUP(C13,'State-wise constituency (2009)'!$C:$C,'State-wise constituency (2009)'!$B:$B,"Not Found") -> 30
... A438: 437 | B438: ZAFAR ALI NAQVI | C438: Kheri | D438: INC | E438: Rs 13,80,047 | F438: =_xlfn.XLOOKUP(C438,'State-wise constituency (2009)'!$C:$C,'State-wise constituency (2009)'!$A:$A,"Not Found") -> Uttar Pradesh | G438: =_xlfn.XLOOKUP(C438,'State-wise constituency (2009)'!$C:$C,'State-wise constituency (2009)'!$B:$B,"Not Found") -> 28

Sheet State-wise constituency (2009)
A1: State | B1: PC No. | C1: PC Name | D1: Category | E1: Winner | F1: Gender | G1: Party | H1: Vote
A2: Andhra Pradesh | B2: 1 | C2: Adilabad | D2: (ST) | E2: Ramesh Rathod | F2: M | G2: TDP | H2: 372268
A3: Andhra Pradesh | B3: 2 | C3: Peddapalli | D3: (SC) | E3: Dr. Gaddam Vivekanand | F3: M | G3: INC | H3: 313748
A4: Andhra Pradesh | B4: 3 | C4: Karimnagar | D4: GEN | E4: Ponnam Prabhakar | F4: M | G4: INC | H4: 317927
A5: Andhra Pradesh | B5: 4 | C5: Nizamabad | D5: GEN | E5: Madhu Goud Yaskhi | F5: M | G5: INC | H5: 296504
A6: Andhra Pradesh | B6: 5 | C6: Zahirabad | D6: GEN | E6: Suresh Kumar Shetkar | F6: M | G6: INC | H6: 395767
A7: Andhra Pradesh | B7: 6 | C7: Medak | D7: GEN | E7: Smt. M. Vijaya Shanthi | F7: F | G7: TRS | H7: 388839
A8: Andhra Pradesh | B8: 7 | C8: Malkajgiri | D8: GEN | E8: Sathyanarayana Sarvey | F8: M | G8: INC | H8: 388368
A9: Andhra Pradesh | B9: 8 | C9: Secunderabad | D9: GEN | E9: M. Anjan Kumar Yadav | F9: M | G9: INC | H9: 340549
A10: Andhra Pradesh | B10: 9 | C10: Hyderabad | D10: GEN | E10: Asaduddin Owaisi | F10: M | G10: AIMIM | H10: 308061
A11: Andhra Pradesh | B11: 10 | C11: Chelvella | D11: GEN | E11: Jaipal Sudini Reddy | F11: M | G11: INC | H11: 420807
A12: Andhra Pradesh | B12: 11 | C12: Mahabubnagar | D12: GEN | E12: Kalva Kuntla Chandrasekhar Rao | F12: M | G12: TRS | H12: 366569
A13: Andhra Pradesh | B13: 12 | C13: Nagarkurnool | D13: (SC) | E13: Dr. M. Jagannath | F13: M | G13: INC | H13: 422745
... A39: Andhra Pradesh | B39: 38 | C39: Kadapa | D39: GEN | E39: Y. S. Jagan Mohan Reddy | F39: M | G39: YSRCP | H39: 542611
A40: Andhra Pradesh | B40: By Polls (2011) | C40: Kadapa | D40: GEN | E40: Y.S.J.M. Reddy | F40: M | G40: YSRCP | H40: 692251
A41: Andhra Pradesh | B41: 39 | C41: Nellore | D41: GEN | E41: Mekapati Rajamohan Reddy | F41: M | G41: YSRCP | H41: 430235
A42: Andhra Pradesh | B42: By Polls (2012) | C42: Nellore | D42: GEN | E42: M.K.Reddy | F42: M | G42: YSRCP | H42: 535436
A43: Andhra Pradesh | B43: 40 | C43: Tirupati | D43: (SC) | E43: Dr. Chinta Mohan | F43: M | G43: INC | H43: 428403
A44: Andhra Pradesh | B44: 41 | C44: Rajampet | D44: GEN | E44: Sai Prathap Annayyagari | F44: M | G44: INC | H44: 423910
A45: Andhra Pradesh | B45: 42 | C45: Chittoor | D45: (SC) | E45: Dr. Naramalli Sivaprasad | F45: M | G45: TDP | H45: 434376
A46: Andaman and Nicobar Islands | B46: 1 | C46: Andaman & Nicobar Islands | D46: GEN | E46: Bishnu Pada Ray | F46: M | G46: BJP | H46: 75211
A47: Arunachal Pradesh | B47: 1 | C47: Arunachal West | D47: (ST) | E47: Takam Sanjoy | F47: M | G47: INC | H47: 140443
A48: Arunachal Pradesh | B48: 2 | C48: Arunachal East | D48: (ST) | E48: Ninong Ering | F48: M | G48: INC | H48: 115423
A49: Assam | B49: 1 | C49: Karimganj | D49: (SC) | E49: Lalit Mohan Suklabaidya | F49: M | G49: INC | H49: 259717
A50: Assam | B50: 2 | C50: Silchar | D50: GEN | E50: Kabindra Purkayastha | F50: M | G50: BJP | H50: 243532
A51: Assam | B51: 3 | C51: Autonomous District | D51: (ST) | E51: Biren Singh Engti | F51: M | G51: INC | H51: 197835
A52: Assam | B52: 4 | C52: Dhubri | D52: GEN | E52: Maulana Badruddin Ajmal | F52: M | G52: AUDF | H52: 540820
A53: Assam | B53: 5 | C53: Kokrajhar | D53: (ST) | E53: Sansuma Khunggur Bwiswmuthiary | F53: M | G53: BOPF | H53: 495211
A54: Assam | B54: 6 | C54: Barpeta | D54: GEN | E54: Ismail Hussain | F54: M | G54: INC | H54: 322137
... A81: Bihar | B81: 19 | C81: Maharajganj | D81: GEN | E81: Uma Shanaker Singh | F81: M | G81: RJD | H81: 211610
A82: Bihar | B82: By Polls (2013) | C82: Maharajganj | D82: GEN | E82: Prabhu Nath Singh | F82: M | G82: RJD | H82: 381452
A83: Bihar | B83: 20 | C83: Saran | D83: GEN | E83: Lalu Prasad | F83: M | G83: RJD | H83: 274209
A84: Bihar | B84: 21 | C84: Hajipur | D84: (SC) | E84: Ram Sundar Das | F84: M | G84: JD(U) | H84: 246715
A85: Bihar | B85: 22 | C85: Ujiarpur | D85: GEN | E85: Smt. Ashwamedh Devi | F85: F | G85: JD(U) | H85: 180082
A86: Bihar | B86: 23 | C86: Samastipur | D86: (SC) | E86: Maheshwar Hazari | F86: M | G86: JD(U) | H86: 259458
A87: Bihar | B87: 24 | C87: Begusarai | D87: GEN | E87: Dr. Monazir Hassan | F87: M | G87: JD(U) | H87: 205680
A88: Bihar | B88: 25 | C88: Khagaria | D88: GEN | E88: Dinesh Chandra Yadav | F88: M | G88: JD(U) | H88: 266964
A89: Bihar | B89: 26 | C89: Bhagalpur | D89: GEN | E89: Syed Shahnawaz Hussain | F89: M | G89: BJP | H89: 228384
A90: Bihar | B90: 27 | C90: Banka | D90: GEN | E90: Digvijay Singh | F90: M | G90: IND | H90: 185762
A91: Bihar | B91: By Polls (2010) | C91: Banka | D91: GEN | E91: Putul Kumari | F91: F | G91: IND | H91: 288958
...
